<?xml version="1.0" ?>
<robot name="canine_blue">

  <material name="blue">
    <color rgba="0.1 0.5 0.8 1.0"/>
  </material>

  <material name="black">
    <color rgba="0.2 0.2 0.2 1"/>
  </material>

  <material name="white">
    <color rgba="0.7 0.7 0.7 1"/>
  </material>

  <link name="base">
    <visual>
      <origin rpy="0 0 0" xyz="0 0 0"/>
      <geometry>
        <box size="0.001 0.001 0.001"/>
      </geometry>
    </visual>
  </link>

  <joint name="floating_base" type="fixed">
    <origin rpy="0 0 0" xyz="0 0 0"/>
    <parent link="base"/>
    <child link="trunk"/>
  </joint>

  <link name="trunk">
    <inertial>
      <origin xyz="0.0 0.0 0.1" rpy="0 0 0"/>
      <mass value="15"/>
      <inertia ixx="0.0422" iyy="0.1961" izz="0.2013" ixy="0.0" iyz="0.0" ixz="0.0"/>
    </inertial>
    <visual>
      <origin xyz="0 0 0" rpy="0 0 0"/>
      <geometry>
        <mesh filename="base_link.stl" scale="0.001 0.001 0.001"/>
      </geometry>
      <material name="blue"/>
    </visual>
    <collision>
      <origin xyz="0 0 -0.011" rpy="0 0 0"/>
      <geometry>
        <box size= "0.38 0.235 0.131"/>
      </geometry>
    </collision>
  </link>

  <!--Front Left-->
  <link name="FL_hip">
    <inertial>
      <origin xyz="0.05900397936818097 0.016029697800056062 2.212166599669565e-09" rpy="0 0 0"/>
      <mass value = "0.8001"/>
      <inertia ixx = "0.00564" iyy = "0.00108127" izz = "0.000706572" ixy = "3.86383e-05" iyz = "0" ixz = "0"/>
    </inertial>
    <visual>
      <origin xyz="-0.185613 -0.065216 -0.000494" rpy="0 0 0"/>
      <geometry>
        <mesh filename="../meshes/FL_Hip_1.stl" scale="0.001 0.001 0.001"/>
      </geometry>
      <material name="black"/>
    </visual>
    <collision>
      <origin xyz="-0.185613 -0.065216 -0.000494" rpy="0 0 0"/>
      <geometry>
        <mesh filename="../meshes/FL_Hip_1.obj" scale="0.001 0.001 0.001"/>
      </geometry>
    </collision>
  </link>

  <link name="FL_thigh">
    <inertial>
      <origin xyz="-0.005387721078168803 0.05564266392885216 -0.026582523402407843" rpy="0 0 0"/>
      <mass value = "1.539"/>
      <inertia ixx = "0.00728621" iyy = "0.00719179" izz = "0.00186201" ixy = "0.000190838" iyz = "0.00118773" ixz = "-0.000781702"/>
    </inertial>
    <visual>
      <origin xyz="-0.256107 -0.062095 -0.000475" rpy="0 0 0"/>
      <geometry>
        <mesh filename="../meshes/FL_thigh_1.stl" scale="0.001 0.001 0.001"/>
      </geometry>
      <material name="black"/>
    </visual>
    <collision>
      <origin xyz="0 0.084 -0.23" rpy="1.57079632679 0 0"/>
      <geometry>
        <cylinder length="0.019" radius="0.015"/>
      </geometry>
    </collision>
  </link>

  <link name="FL_calf">
    <inertial>
      <origin xyz="0.012113413386121074 -0.01111206629631091 -0.12498448456445585" rpy="0 0 0"/>
      <mass value = "0.268"/>
      <inertia ixx = "0.00278652" iyy = "0.00280706" izz = "4.43533e-05" ixy = "-0" iyz = "3.86975e-06" ixz = "-1.99441e-05"/>
    </inertial>
    <visual>
      <origin xyz="0.256221 0.1424 0.230545" rpy="0 0 0"/>
      <geometry>
        <mesh filename="../meshes/HR_calf_1.stl" scale="0.001 0.001 0.001"/>
      </geometry>
      <material name="white"/>
    </visual>
    <collision>
      <origin xyz="0 0 -0.23" rpy="1.57079632679 0 0"/>
      <geometry>
        <cylinder length="0.024" radius="0.025"/>
      </geometry>
    </collision>
  </link>

  <!--  Front Right -->
  <link name="FR_hip">
    <inertial>
      <origin xyz="0.05900397936818097 -0.016029697800056062 2.212166599669565e-09" rpy="0 0 0"/>
      <mass value = "0.8001"/>
      <inertia ixx = "0.00564" iyy = "0.00108127" izz = "0.000706572" ixy = "-3.86383e-05" iyz = "0" ixz = "0"/>
    </inertial>
    <visual>
      <origin xyz="-0.185389 0.06478 0.000488" rpy="0 0 0"/>
      <geometry>
        <mesh filename="../meshes/FR_Hip_1.stl" scale="0.001 0.001 0.001"/>
      </geometry>
      <material name="black"/>
    </visual>
    <collision>
      <origin xyz="-0.185389 0.06478 0.000488" rpy="0 0 0"/>
      <geometry>
        <mesh filename="../meshes/FR_Hip_1.obj" scale="0.001 0.001 0.001"/>
      </geometry>
    </collision>
  </link>

  <link name="FR_thigh">
    <inertial>
      <origin xyz="-0.005387721078168803 -0.05564266392885216 -0.026582523402407843" rpy="0 0 0"/>
      <mass value = "1.539"/>
      <inertia ixx = "0.00728621" iyy = "0.00719179" izz = "0.00186201" ixy = "-0.000190838" iyz = "-0.00118773" ixz = "-0.000781702"/>
    </inertial>
    <visual>
      <origin xyz="-0.255894 0.061902 0.000472" rpy="0 0 0"/>
      <geometry>
        <mesh filename="../meshes/FR_thigh_1.stl" scale="0.001 0.001 0.001"/>
      </geometry>
      <material name="black"/>
    </visual>
    <collision>
      <origin xyz="0 -0.084 -0.23" rpy="1.57079632679 0 0"/>
      <geometry>
        <cylinder length="0.019" radius="0.015"/>
      </geometry>
    </collision>
  </link>

  <link name="FR_calf">
    <inertial>
      <origin xyz="0.012113413386121074 0.01111206629631091 -0.12498448456445585" rpy="0 0 0"/>
      <mass value = "0.268"/>
      <inertia ixx = "0.00278652" iyy = "0.00280706" izz = "4.43533e-05" ixy = "-0" iyz = "-3.86975e-06" ixz = "-1.99441e-05"/>
    </inertial>
    <visual>
      <origin xyz="0.256221 0.1424 0.230545" rpy="0 0 0"/>
      <geometry>
        <mesh filename="../meshes/HR_calf_1.stl" scale="0.001 0.001 0.001"/>
      </geometry>
      <material name="white"/>
    </visual>
    <collision>
      <origin xyz="0 0 -0.23" rpy="1.57079632679 0 0"/>
      <geometry>
        <cylinder length="0.024" radius="0.025"/>
      </geometry>
    </collision>
  </link>

  <!--  Hind Left-->
  <link name="HL_hip">
    <inertial>
      <origin xyz="-0.05900397936818097 0.016029697800056062 2.212166599669565e-09" rpy="0 0 0"/>
      <mass value = "0.8001"/>
      <inertia ixx = "0.00564" iyy = "0.00108127" izz = "0.000706572" ixy = "-3.86383e-05" iyz = "0" ixz = "0"/>
    </inertial>
    <visual>
      <origin xyz="0.185387 -0.065854 -0.000501" rpy="0 0 0"/>
      <geometry>
        <mesh filename="../meshes/HL_Hip_1.stl" scale="0.001 0.001 0.001"/>
      </geometry>
      <material name="black"/>
    </visual>
    <collision>
      <origin xyz="0.185387 -0.065854 -0.000501" rpy="0 0 0"/>
      <geometry>
        <mesh filename="../meshes/HL_Hip_1.obj" scale="0.001 0.001 0.001"/>
      </geometry>
    </collision>
  </link>

  <link name="HL_thigh">
    <inertial>
      <origin xyz="0.005387721078168803 0.05564266392885216 -0.026582523402407843" rpy="0 0 0"/>
      <mass value = "1.539"/>
      <inertia ixx = "0.00728621" iyy = "0.00719179" izz = "0.00186201" ixy = "-0.000190838" iyz = "0.00118773" ixz = "0.000781702"/>
    </inertial>
    <visual>
      <origin xyz="0.255892 -0.062976 -0.000485" rpy="0 0 0"/>
      <geometry>
        <mesh filename="../meshes/HL_thigh_1.stl" scale="0.001 0.001 0.001"/>
      </geometry>
      <material name="black"/>
    </visual>
    <collision>
      <origin xyz="0 0.084 -0.23" rpy="1.57079632679 0 0"/>
      <geometry>
        <cylinder length="0.019" radius="0.015"/>
      </geometry>
    </collision>
  </link>

  <link name="HL_calf">
    <inertial>
      <origin xyz="-0.012113413386121074 -0.01111206629631091 -0.12498448456445585" rpy="0 0 0"/>
      <mass value = "0.268"/>
      <inertia ixx = "0.00278652" iyy = "0.00280706" izz = "4.43533e-05" ixy = "0" iyz = "3.86975e-06" ixz = "1.99441e-05"/>
    </inertial>
    <visual>
      <origin xyz="0.256221 0.1424 0.230545" rpy="0 0 0"/>
      <geometry>
        <mesh filename="../meshes/HR_calf_1.stl" scale="0.001 0.001 0.001"/>
      </geometry>
      <material name="white"/>
    </visual>
    <collision>
      <origin xyz="0 0 -0.23" rpy="1.57079632679 0 0"/>
      <geometry>
        <cylinder length="0.024" radius="0.025"/>
      </geometry>
    </collision>
  </link>

  <!--  Hind Right -->
  <link name="HR_hip">
    <inertial>
      <origin xyz="-0.05900397936818097 -0.016029697800056062 2.212166599669565e-09" rpy="0 0 0"/>
      <mass value = "0.8001"/>
      <inertia ixx = "0.00564" iyy = "0.00108127" izz = "0.000706572" ixy = "3.86383e-05" iyz = "0" ixz = "0"/>
    </inertial>
    <visual>
      <origin xyz="0.185611 0.064142 0.000481" rpy="0 0 0"/>
      <geometry>
        <mesh filename="../meshes/HR_Hip_1.stl" scale="0.001 0.001 0.001"/>
      </geometry>
      <material name="black"/>
    </visual>
    <collision>
      <origin xyz="0.185611 0.064142 0.000481" rpy="0 0 0"/>
      <geometry>
        <mesh filename="../meshes/HR_Hip_1.obj" scale="0.001 0.001 0.001"/>
      </geometry>
    </collision>
  </link>

  <link name="HR_thigh">
    <inertial>
      <origin xyz="0.005387721078168803 -0.05564266392885216 -0.026582523402407843" rpy="0 0 0"/>
      <mass value = "1.539"/>
      <inertia ixx = "0.00728621" iyy = "0.00719179" izz = "0.00186201" ixy = "0.000190838" iyz = "-0.00118773" ixz = "0.000781702"/>
    </inertial>
    <visual>
      <origin xyz="0.256105 0.06102 0.000462" rpy="0 0 0"/>
      <geometry>
        <mesh filename="../meshes/HR_thigh_1.stl" scale="0.001 0.001 0.001"/>
      </geometry>
      <material name="black"/>
    </visual>
    <collision>
      <origin xyz="0 -0.084 -0.23" rpy="1.57079632679 0 0"/>
      <geometry>
        <cylinder length="0.024" radius="0.025"/>
      </geometry>
    </collision>
  </link>

  <link name="HR_calf">
    <inertial>
      <origin xyz="-0.012113413386121074 0.01111206629631091 -0.12498448456445585" rpy="0 0 0"/>
      <mass value = "0.268"/>
      <inertia ixx = "0.00278652" iyy = "0.00280706" izz = "4.43533e-05" ixy = "0" iyz = "-3.86975e-06" ixz = "1.99441e-05"/>
    </inertial>
    <visual>
      <origin xyz="0.256221 0.1424 0.230545" rpy="0 0 0"/>
      <geometry>
        <mesh filename="../meshes/HR_calf_1.stl" scale="0.001 0.001 0.001"/>
      </geometry>
      <material name="white"/>
    </visual>
    <collision>
      <origin xyz="0 0 -0.23" rpy="1.57079632679 0 0"/>
      <geometry>
        <cylinder length="0.024" radius="0.025"/>
      </geometry>
    </collision>
  </link>

  <!--  joint -->
  <!--leg-->
  <joint name="FL_HIP" type="revolute">
    <origin xyz="0.1935 0.075 0.0" rpy="0 0 0"/>
    <parent link="trunk"/>
    <child link="FL_hip"/>
    <axis xyz="1 0 0"/>
  </joint>

  <joint name="FL_THIGH" type="revolute">
    <origin xyz="0.075 -0.003 0.0" rpy="0 0 0"/>
    <parent link="FL_hip"/>
    <child link="FL_thigh"/>
    <axis xyz="0 1 0"/>
  </joint>

  <joint name="FL_KNEE" type="revolute">
    <origin xyz="0 0.085 -0.23" rpy="0 0 0"/>
    <parent link="FL_thigh"/>
    <child link="FL_calf"/>
    <axis xyz="0 1 0"/>
  </joint>

  <joint name="FR_HIP" type="revolute">
    <origin xyz="0.1935 -0.075 0.0" rpy="0 0 0"/>
    <parent link="trunk"/>
    <child link="FR_hip"/>
    <axis xyz="1 0 0"/>
  </joint>

  <joint name="FR_THIGH" type="revolute">
    <origin xyz="0.075 0.003 0.0" rpy="0 0 0"/>
    <parent link="FR_hip"/>
    <child link="FR_thigh"/>
    <axis xyz="0 1 0"/>
  </joint>

  <joint name="FR_KNEE" type="revolute">
    <origin xyz="0 -0.085 -0.23" rpy="0 0 0"/>
    <parent link="FR_thigh"/>
    <child link="FR_calf"/>
    <axis xyz="0 1 0"/>
  </joint>

  <joint name="HL_HIP" type="revolute">
    <origin xyz="-0.1935 0.075 0.0" rpy="0 0 0"/>
    <parent link="trunk"/>
    <child link="HL_hip"/>
    <axis xyz="1 0 0"/>
  </joint>

  <joint name="HL_THIGH" type="revolute">
    <origin xyz="-0.075 -0.003 0.0" rpy="0 0 0"/>
    <parent link="HL_hip"/>
    <child link="HL_thigh"/>
    <axis xyz="0 1 0"/>
  </joint>

  <joint name="HL_KNEE" type="revolute">
    <origin xyz="0 0.085 -0.23" rpy="0 0 0"/>
    <parent link="HL_thigh"/>
    <child link="HL_calf"/>
    <axis xyz="0 1 0"/>
  </joint>

  <joint name="HR_HIP" type="revolute">
    <origin xyz="-0.1935 -0.075 0.0" rpy="0 0 0"/>
    <parent link="trunk"/>
    <child link="HR_hip"/>
    <axis xyz="1 0 0"/>
  </joint>

  <joint name="HR_THIGH" type="revolute">
    <origin xyz="-0.075 0.003 0.0" rpy="0 0 0"/>
    <parent link="HR_hip"/>
    <child link="HR_thigh"/>
    <axis xyz="0 1 0"/>
  </joint>

  <joint name="HR_KNEE" type="revolute">
    <origin xyz="0 -0.085 -0.23" rpy="0 0 0"/>
    <parent link="HR_thigh"/>
    <child link="HR_calf"/>
    <axis xyz="0 1 0"/>
  </joint>
</robot>